<mujoco>
  <option timestep="0.01"/>

  <include file="./common/skybox.xml"/>
  <include file="./common/visual.xml"/>
  <include file="./common/materials.xml"/>

  <compiler angle="radian" meshdir="meshes"/>
  <option timestep=".005"/>

  <default>
        <light castshadow="true" diffuse="1 1 1" />
        <camera fovy="60" />
  </default>

  <asset>
        <!-- arm models -->
        <mesh file="PiernaDerecha.stl" smoothnormal="true"/>
        <mesh file="PiernaIzquierda.stl" smoothnormal="true"/>
        <mesh file="PiernaDelantera.stl" smoothnormal="true"/>
        <mesh file="Cuerpo.stl" smoothnormal="true"/>

    </asset>

    <worldbody>
      <geom name="floor" type="plane" size="5000 5000 5" material="grid" friction="1.5" mass='10.00'/>

<!---
      <geom name="barril" type="cylinder" size="20 20 20" material="target"  pos="0 10 2"/>
      <geom name="barril2" type="cylinder" size="2 2 2" material="target"  pos="0 20 2"/>
      <geom name="barril3" type="cylinder" size="2 2 2" material="target"  pos="20 5 2"/>
      <geom name="barril4" type="cylinder" size="2 2 2" material="target"  pos="-15 0 2"/>
      <geom name="barril5" type="cylinder" size="2 2 2" material="target"  pos="30 -10 2"/>
      <geom name="barril6" type="cylinder" size="2 2 2" material="target"  pos="40 -15 2"/>
      <geom name="barril7" type="cylinder" size="2 2 2" material="target"  pos="-5 -32 2"/>
      <geom name="barril8" type="cylinder" size="2 2 2" material="target"  pos="0 -13 2"/>
      <geom name="wall0" type="box" material ="target_default" size="10 1 10" pos="0 -10 10"/>
-->
      <geom name="wall1" type="box" material ="target_default" size="50 1 10" pos="0 5000 10"/>
      <geom name="wall2" type="box" size="5000 1 1000" material ="target_default" pos="0 -5000 10"/>
      <geom name="wall3" type="box" size="5000 1 1000" material ="target_default"  pos="-5000 0 10" euler="0 0 1.5567"/>
      <geom name="wall4" type="box" size="5000 1 1000" material ="target_default"  pos="5000 0 10" euler="0 0 1.5567"/>




      <body name="body_link" pos="0 0 200" euler="1.6 0 0">
          <!-- freejoint APLICA FISICAS -->
          <freejoint name="root"/>
          <geom name="body" type="mesh" mesh="Cuerpo" pos="0 0 0" mass="1.00"/>

          <site name="rf_00" type="sphere" pos="0 -3 2" euler=".3 0 0" size=".05 .05 .05" rgba="0 0 255 1"/>
          <site name="rf_01" type="sphere" pos="0.7 -2.8 2" euler=".3 -.9 0" size=".05 .05 .05" rgba="0 0 255 1"/>
          <site name="rf_02" type="sphere" pos="1.2 -2.3 2" euler=".3 .9 0" size=".05 .05 .05" rgba="0 0 255 1"/>


              <body name="leftFoot_link" pos="0 0 0">
                  <geom name="PiernaIzquierda" type="mesh" mesh="PiernaIzquierda" mass="1.00" pos="0 0 0"/>
                  <!-- Join left foot to LeftArm -->
                  <site name="joint_lf" type="cylinder" size="5 8" pos="103 -150 -110" euler="0 1.6 0" rgba="255 0 0 0.8"/>
                  <!--<joint name="joint3_lf" axis="0 0 -1" pos="0 0 0"/>-->
                  <body name="rueda_izquierda">
                    <geom name="rueda_i" type="cylinder" size="30 8" mass="0.4" friction="1.5" pos="103 -150 -110" euler="0 1.56999 0" rgba="100 255 0 0.8"/>
                    <joint name="rueda_i" type="hinge" axis="1 0 0" pos="103 -150 -110" />
                  </body>
              </body>

              <body name="rightFoot_link" pos="0 0 0">
                  <geom name="PiernaDerecha" type="mesh" mesh="PiernaDerecha" mass="1.00" pos="0 0 0"/>
                  <!-- Join RightFoot to RightArm -->
                  <site name="joint_rf" type="cylinder" size="0.3 0.009" pos="-102 -150 -110" euler="0.48 0 0" rgba="255 0 0 0.8"/>
                  <!--<joint name="joint4_rf" axis="-1 0 0" pos="0 0 0"/>-->
                  <body name="rueda_derecha">
                    <geom name="rueda_d" type="cylinder" size="30 8" mass="0.4" friction="1.5" pos="-102 -150 -110" euler="0 1.56999 0" rgba="100 255 0 0.8"/>
                    <joint name="rueda_d" type="hinge" axis="1 0 0" pos="-102 -150 -110"/>
                  </body>
              </body>



              <body name="centralFoot_link" pos="0 0 0">
                  <geom name="PiernaDelantera" type="mesh" mesh="PiernaDelantera" friction="0"  mass="10.00" pos="0 0 0"/>
                  <joint name="PiernaDelantera" type="hinge" axis="0 1 0" pos="0 -40 0" armature="0.5" limited="true" range="-0.785398 0.785398"/>


                  <!-- Join RightFoot to RightArm -->
                  <!--<joint name="joint6_cf" axis="-1 0 0" pos="0 0 0"/>-->
                  <body name="rueda_central">
                    <geom name="rueda_c" type="cylinder" size="30 8" mass="0.4" friction="0" pos="0 -145 35" euler="0 1.56999 0" rgba="200 255 0 0.8"/>
                    <joint name="rueda_c" type="hinge" axis="1 0 0" pos="0 -145 35"/>

                  </body>

              </body>
        </body>

    </worldbody>
    <actuator>

      <velocity name="mr_i" joint="rueda_i" kv="10" gear="1.4" forcelimited="true" forcerange="-500 500"/>
      <velocity name="mr_d" joint="rueda_d" kv="10" gear="1.4" forcelimited="true" forcerange="-500 500"/>
      <position name ="central" joint='PiernaDelantera' kp="100" />


<!--
    <general name="mr_i" joint="rueda_i" ctrlrange="-100 100" ctrllimited="true" gainprm="500"/>
    <general name="mr_d" joint="rueda_d" ctrlrange="-100 100" ctrllimited="true" gainprm="500"/>
    <position name="mr_c" joint="rueda_c" kp="3000" gear="0.5" ctrllimited="true" ctrlrange="-3.14159 3.14159"/>
-->
    </actuator>
    <sensor>
    <rangefinder name="ultrasonic_0" site="rf_00" />
    <rangefinder name="ultrasonic_1" site="rf_01" />
    <rangefinder name="ultrasonic_2" site="rf_02" />
  </sensor>



</mujoco>
