<mujoco>

  <include file="./common/skybox.xml"/>
  <include file="./common/visual.xml"/>
  <include file="./common/materials.xml"/>

  <compiler angle="radian" meshdir="meshes"/>
  <option timestep=".005"/>

  <default>
        <light castshadow="true" diffuse="1 1 1" />
        <camera fovy="60" />
  </default>

  <asset>
        <!-- arm models -->
        <mesh file="Mate_Ruiz-Head.stl" smoothnormal="false"/>
        <mesh file="Mate_Ruiz-Body.stl" smoothnormal="true"/>
        <mesh file="Mate_Ruiz-LeftArm.stl" smoothnormal="true"/>
        <mesh file="Mate_Ruiz-LeftFoot.stl" smoothnormal="true"/>
        <mesh file="Mate_Ruiz-RightArm.stl" smoothnormal="true"/>
        <mesh file="Mate_Ruiz-RightFoot.stl" smoothnormal="true"/>
        <mesh file="Mate_Ruiz-CentralSupport.stl" smoothnormal="true"/>
        <mesh file="Mate_Ruiz-CentralFoot.stl" smoothnormal="true"/>

    </asset>

    <worldbody>
      <geom name="floor" type="plane" size="50 50 .5" material="grid" friction="1.5"/>


      <geom name="barril" type="cylinder" size="2 2 2" material="target"  pos="0 10 2"/>
      <geom name="barril2" type="cylinder" size="2 2 2" material="target"  pos="0 20 2"/>
      <geom name="barril3" type="cylinder" size="2 2 2" material="target"  pos="20 5 2"/>
      <geom name="barril4" type="cylinder" size="2 2 2" material="target"  pos="-15 0 2"/>
      <geom name="barril5" type="cylinder" size="2 2 2" material="target"  pos="30 -10 2"/>
      <geom name="barril6" type="cylinder" size="2 2 2" material="target"  pos="40 -15 2"/>
      <geom name="barril7" type="cylinder" size="2 2 2" material="target"  pos="-5 -32 2"/>
      <geom name="barril8" type="cylinder" size="2 2 2" material="target"  pos="0 -13 2"/>
      <geom name="wall0" type="box" material ="target_default" size="10 1 10" pos="0 -10 10"/>

      <geom name="wall1" type="box" material ="target_default" size="50 1 10" pos="0 50 10"/>
      <geom name="wall2" type="box" size="50 1 10" material ="target_default" pos="0 -50 10"/>
      <geom name="wall3" type="box" size="50 1 10" material ="target_default"  pos="-50 0 10" euler="0 0 1.5567"/>
      <geom name="wall4" type="box" size="50 1 10" material ="target_default"  pos="50 0 10" euler="0 0 1.5567"/>


      <body name="body_link" pos="0 0 1">
          <!-- freejoint APLICA FISICAS -->
          <freejoint name="root"/>
          <geom name="Mate_Ruiz-Body" type="box" size="2 3 .5" pos="0 0 4"/>

          <site name="rf_02" type="sphere" pos="1.2 -2.3 4" euler="1.6 0.45 0" size=".05 .05 .05" rgba="0 0 255 1"/>
          <site name="rf_04" type="sphere" pos="-1.2 -2.3 4" euler="1.6 -0.45 0" size=".05 .05 .05" rgba="0 0 255 1"/>
          <site name="rf_05" type="sphere" pos="0 0.1 4" euler="-1.6 0 0" size=".05 .05 .05" rgba="0 0 255 1"/>


          <body name="leftArm_link" pos="0 2.5 0">
              <geom name="Mate_Ruiz-LeftArm" type="mesh" mesh="Mate_Ruiz-LeftArm" size="0.1 0.1 0.1" pos="0 0 0"/>
              <!-- Join left arm to body -->
              <site name="joint_la" type="cylinder" size="0.25 0.012" pos="-1.47 -0.75 3.85" euler="0 1.6 0" rgba="255 0 0 0.8"/>
              <!--<joint name="joint0_la" axis="-1 0 0" pos="0 0 0"/>-->

              <body name="leftFoot_link" pos="0 0 0">
                  <geom name="Mate_Ruiz-LeftFoot" type="mesh" mesh="Mate_Ruiz-LeftFoot" size="0.1 0.1 0.1" pos="0 0 0"/>
                  <!-- Join left foot to LeftArm -->
                  <site name="joint_lf" type="cylinder" size="0.3 0.009" pos="-2.1 0.9 0.7" euler="0.48 0 0" rgba="255 0 0 0.8"/>
                  <!--<joint name="joint3_lf" axis="0 0 -1" pos="0 0 0"/>-->
                  <body name="rueda_izquierda">
                    <geom name="rueda_i" type="cylinder" size="0.15 0.2" friction="1.5" pos="-2.1 1.3 -0.1" euler="0 1.56999 0" rgba="100 255 0 0.8"/>
                    <joint name="rueda_i" type="hinge" axis="1 0 0" pos="-2.1 1.3 -0.1"/>
                  </body>
              </body>
          </body>

          <body name="rightArm_link" pos="0 2.5 0">
              <geom name="Mate_Ruiz-RightArm" type="mesh" mesh="Mate_Ruiz-RightArm" size="0.1 0.1 0.1" pos="0 0 0"/>
              <!-- Join RightArm to body -->
              <site name="joint_ra" type="cylinder" size="0.25 0.012" pos="1.4 -0.8 3.8" euler="0 1.6 0" rgba="255 0 0 0.8"/>
              <!--<joint name="joint1_ra" axis="-1 0 0" pos="0 0 0"/>-->

              <body name="rightFoot_link" pos="0 0 0">
                  <geom name="Mate_Ruiz-RightFoot" type="mesh" mesh="Mate_Ruiz-RightFoot" size="0.1 0.1 0.1" pos="0 0 0"/>
                  <!-- Join RightFoot to RightArm -->
                  <site name="joint_rf" type="cylinder" size="0.3 0.009" pos="2.1 0.9 0.7" euler="0.48 0 0" rgba="255 0 0 0.8"/>
                  <!--<joint name="joint4_rf" axis="-1 0 0" pos="0 0 0"/>-->
                  <body name="rueda_derecha">
                    <geom name="rueda_d" type="cylinder" size="0.15 0.2" friction="1.5" pos="2.1 1.3 -0.1" euler="0 1.56999 0" rgba="100 255 0 0.8"/>
                    <joint name="rueda_d" type="hinge" axis="1 0 0" pos="2.1 1.3 -0.1"/>
                  </body>
              </body>
          </body>

          <body name="centralSupport_link" pos="0 0 0">
              <geom name="Mate_Ruiz-CentralSupport" type="cylinder" size=".3 1" pos="0 -1.5 3" euler=".5 0 0"/>
              <geom name="Mate_Ruiz-CentralSupport2" type="cylinder" size=".3 1" pos="0 -1.5 1.5" euler="-.5 0 0"/>

              <joint name="rueda_c" type="hinge" axis="0 0 1" pos="0 -2 -0.1"/>

              <!-- Join RightArm to body -->
              <site name="joint_cs" type="cylinder" size="0.3 0.009" pos="0 -2 0.9" euler="-0.3 0 0" rgba="255 0 0 0.8"/>
              <!--<joint name="joint5_cs" axis="-1 0 0" pos="0 0 0"/>-->

              <body name="centralFoot_link" pos="0 0 0">
                  <geom name="Mate_Ruiz-CentralFoot" type="mesh" mesh="Mate_Ruiz-CentralFoot" size="0.1 0.1 0.1" pos="0 0 0"/>
                  <!-- Join RightFoot to RightArm -->
                  <site name="joint_cf" type="cylinder" size="0.3 0.009" pos="0 -2 0.465" euler="-0.3 0 0" rgba="255 0 0 0.8"/>
                  <!--<joint name="joint6_cf" axis="-1 0 0" pos="0 0 0"/>-->
                  <body name="rueda_central">
                    <geom name="rueda_c" type="cylinder" size="0.15 0.05" friction="1.5" pos="0 -2 -0.1" euler="0 1.56999 0" rgba="200 255 0 0.8"/>

                    <joint name="rueda_c_derecho" type="hinge" axis="1 0 0" pos="0 -2 -0.1"/>
                  </body>

              </body>
          </body>
      </body>
<!--
      <body name="ball" pos="0 -7 4">
        <freejoint name="ball_root"/>
        <geom name="ball" size="1" material="self" priority="1" condim="6" friction=".7 .005 .005"
              solref="-10000 -30"/>
        <light name="ball_light" pos="0 0 4" mode="trackcom"/>
      </body>
-->
<!--
      <body name="Completo" pos="10 10 200">
        <freejoint name="root2"/>
        <geom name="robot" type="mesh" mesh="CuerpoCompleto2"/>

      </body>
-->
    </worldbody>
    <actuator>

      <general name="mr_i" joint="rueda_i" ctrlrange="-5 5" ctrllimited="true" gainprm="500"/>
      <general name="mr_d" joint="rueda_d" ctrlrange="-5 5" ctrllimited="true" gainprm="500"/>
      <position name="mr_c" joint="rueda_c" kp="3000" gear="0.5" ctrllimited="true" ctrlrange="-3.14159 3.14159"/>

    </actuator>
    <sensor>
      <rangefinder name="ultrasonic_2" site="rf_02" />
      <rangefinder name="ultrasonic_4" site="rf_04" />
      <rangefinder name="ultrasonic_5" site="rf_05" />
    </sensor>
</mujoco>
